<?xml version="1.0" ?>
<!-- =================================================================================== -->
<!-- |    This document was autogenerated by xacro from quad2.xacro                    | -->
<!-- |    EDITING THIS FILE BY HAND IS NOT RECOMMENDED                                 | -->
<!-- =================================================================================== -->
<robot name="quad2" xmlns:xacro="http://www.ros.org/wiki/xacro">
  <material name="red">
    <color rgba="1 0 0 1"/>
  </material>
  <material name="blue">
    <color rgba="0 0 1 1"/>
  </material>
  <!--Root Link is defined as kdl does not support a root link with inertia
element. Adding the element creates problem in gazebo. The cog or the inertia of the
base link is somehow affected. Thus causing large instability in the model.-->
  <!--link name = "root_link">
</link-->
  <link name="world"/>
  <joint name="dummy_link" type="floating">
    <parent link="world"/>
    <child link="base_link"/>
  </joint>
  <link name="base_link">
    <collision>
      <geometry>
        <box size="0.3 0.3 0.14"/>
      </geometry>
    </collision>
    <visual>
      <geometry>
        <box size="0.3 0.3 0.14"/>
      </geometry>
      <material name="red">
        <color rgba="0 0 1 1"/>
      </material>
    </visual>
    <inertial>
      <mass value="10"/>
      <inertia ixx="0.0913333333333" ixy="0.0" ixz="0.0" iyy="0.0913333333333" iyz="0.0" izz="0.15"/>
    </inertial>
  </link>
  <gazebo reference="base_link">
    <kp>100000000.0</kp>
    <kd>100000000.0</kd>
    <mu1>1000000</mu1>
    <mu2>1000000</mu2>
    <material>Gazebo/Red</material>
  </gazebo>
  <link name="link1_lf">
    <collision>
      <origin rpy="0 1.570797 0" xyz="0.044 0 0"/>
      <geometry>
        <cylinder length="0.088" radius="0.016"/>
      </geometry>
    </collision>
    <visual>
      <geometry>
        <cylinder length="0.088" radius="0.016"/>
      </geometry>
      <origin rpy="0 1.570797 0" xyz="0.044 0 0"/>
      <material name="blue"/>
    </visual>
    <inertial>
      <origin rpy="0 0 0" xyz="0.044 0 0"/>
      <mass value="0.9"/>
      <inertia ixx="0.0001152" ixy="0.0" ixz="0.0" iyy="0.0006384" iyz="0.0" izz="0.0006384"/>
    </inertial>
  </link>
  <gazebo reference="link1_lf">
    <kp>100000000.0</kp>
    <kd>10000000.0</kd>
    <mu1>1000000</mu1>
    <mu2>1000000</mu2>
    <material>Gazebo/Blue</material>
  </gazebo>
  <joint name="joint1_lf" type="revolute">
    <origin rpy="0 0 0.785" xyz="0.15 0.15 0"/>
    <axis xyz="0 0 -1"/>
    <limit effort="200.0" lower="-1.57075" upper="1.57075" velocity="4"/>
    <parent link="base_link"/>
    <child link="link1_lf"/>
    <dynamics damping="10.0"/>
  </joint>
  <link name="link2_lf">
    <collision>
      <geometry>
        <cylinder length="0.168" radius="0.016"/>
      </geometry>
      <origin rpy="0 -1.570797 0" xyz="0.084 0 0"/>
    </collision>
    <visual>
      <geometry>
        <cylinder length="0.168" radius="0.016"/>
      </geometry>
      <origin rpy="0 -1.570797 0" xyz="0.084 0 0"/>
      <material name="blue"/>
    </visual>
    <inertial>
      <origin rpy="0 0 0" xyz="0.084 0 0"/>
      <mass value="0.8"/>
      <inertia ixx="0.0001024" ixy="0.0" ixz="0.0" iyy="0.0019328" iyz="0.0" izz="0.0019328"/>
    </inertial>
  </link>
  <gazebo reference="link2_lf">
    <kp>100000000.0</kp>
    <kd>10000000.0</kd>
    <mu1>1000000</mu1>
    <mu2>1000000</mu2>
    <material>Gazebo/Blue</material>
  </gazebo>
  <joint name="joint2_lf" type="revolute">
    <origin rpy="1.570797 0 0" xyz="0.088 0 0"/>
    <axis xyz="0 0 -1"/>
    <limit effort="200.0" lower="-1.57075" upper="1.57075" velocity="4"/>
    <parent link="link1_lf"/>
    <child link="link2_lf"/>
    <dynamics damping="10.0"/>
  </joint>
  <link name="link3_lf">
    <collision>
      <geometry>
        <cylinder length="0.28" radius="0.016"/>
      </geometry>
      <origin rpy="0 -1.570797 0" xyz="0.14 0 0"/>
    </collision>
    <visual>
      <geometry>
        <cylinder length="0.28" radius="0.016"/>
      </geometry>
      <origin rpy="0 -1.570797 0" xyz="0.14 0 0"/>
      <material name="blue"/>
    </visual>
    <inertial>
      <origin rpy="0 0 0" xyz="0.14 0 0"/>
      <mass value="1.0"/>
      <inertia ixx="0.000128" ixy="0.0" ixz="0.0" iyy="0.00659733333333" iyz="0.0" izz="0.00659733333333"/>
    </inertial>
  </link>
  <gazebo reference="link3_lf">
    <kp>100000000.0</kp>
    <kd>10000000.0</kd>
    <mu1>1000000</mu1>
    <mu2>1000000</mu2>
    <material>Gazebo/Blue</material>
  </gazebo>
  <joint name="joint3_lf" type="revolute">
    <origin rpy="0 0 -1.570797" xyz="0.168 0 0"/>
    <axis xyz="0 0 -1"/>
    <limit effort="200.0" lower="-3.14" upper="1.57075" velocity="4"/>
    <parent link="link2_lf"/>
    <child link="link3_lf"/>
    <dynamics damping="10.0"/>
  </joint>
  <link name="link1_lr">
    <collision>
      <origin rpy="0 1.570797 0" xyz="0.044 0 0"/>
      <geometry>
        <cylinder length="0.088" radius="0.016"/>
      </geometry>
    </collision>
    <visual>
      <geometry>
        <cylinder length="0.088" radius="0.016"/>
      </geometry>
      <origin rpy="0 1.570797 0" xyz="0.044 0 0"/>
      <material name="blue"/>
    </visual>
    <inertial>
      <origin rpy="0 0 0" xyz="0.044 0 0"/>
      <mass value="0.9"/>
      <inertia ixx="0.0001152" ixy="0.0" ixz="0.0" iyy="0.0006384" iyz="0.0" izz="0.0006384"/>
    </inertial>
  </link>
  <gazebo reference="link1_lr">
    <kp>100000000.0</kp>
    <kd>10000000.0</kd>
    <mu1>1000000</mu1>
    <mu2>1000000</mu2>
    <material>Gazebo/Blue</material>
  </gazebo>
  <joint name="joint1_lr" type="revolute">
    <origin rpy="0 0 2.355" xyz="-0.15 0.15 0"/>
    <axis xyz="0 0 -1"/>
    <limit effort="200.0" lower="-1.57075" upper="1.57075" velocity="4"/>
    <parent link="base_link"/>
    <child link="link1_lr"/>
    <dynamics damping="10.0"/>
  </joint>
  <link name="link2_lr">
    <collision>
      <geometry>
        <cylinder length="0.168" radius="0.016"/>
      </geometry>
      <origin rpy="0 -1.570797 0" xyz="0.084 0 0"/>
    </collision>
    <visual>
      <geometry>
        <cylinder length="0.168" radius="0.016"/>
      </geometry>
      <origin rpy="0 -1.570797 0" xyz="0.084 0 0"/>
      <material name="blue"/>
    </visual>
    <inertial>
      <origin rpy="0 0 0" xyz="0.084 0 0"/>
      <mass value="0.8"/>
      <inertia ixx="0.0001024" ixy="0.0" ixz="0.0" iyy="0.0019328" iyz="0.0" izz="0.0019328"/>
    </inertial>
  </link>
  <gazebo reference="link2_lr">
    <kp>100000000.0</kp>
    <kd>10000000.0</kd>
    <mu1>1000000</mu1>
    <mu2>1000000</mu2>
    <material>Gazebo/Blue</material>
  </gazebo>
  <joint name="joint2_lr" type="revolute">
    <origin rpy="1.570797 0 0" xyz="0.088 0 0"/>
    <axis xyz="0 0 -1"/>
    <limit effort="200.0" lower="-1.57075" upper="1.57075" velocity="4"/>
    <parent link="link1_lr"/>
    <child link="link2_lr"/>
    <dynamics damping="10.0"/>
  </joint>
  <link name="link3_lr">
    <collision>
      <geometry>
        <cylinder length="0.28" radius="0.016"/>
      </geometry>
      <origin rpy="0 -1.570797 0" xyz="0.14 0 0"/>
    </collision>
    <visual>
      <geometry>
        <cylinder length="0.28" radius="0.016"/>
      </geometry>
      <origin rpy="0 -1.570797 0" xyz="0.14 0 0"/>
      <material name="blue"/>
    </visual>
    <inertial>
      <origin rpy="0 0 0" xyz="0.14 0 0"/>
      <mass value="1.0"/>
      <inertia ixx="0.000128" ixy="0.0" ixz="0.0" iyy="0.00659733333333" iyz="0.0" izz="0.00659733333333"/>
    </inertial>
  </link>
  <gazebo reference="link3_lr">
    <kp>100000000.0</kp>
    <kd>10000000.0</kd>
    <mu1>1000000</mu1>
    <mu2>1000000</mu2>
    <material>Gazebo/Blue</material>
  </gazebo>
  <joint name="joint3_lr" type="revolute">
    <origin rpy="0 0 -1.570797" xyz="0.168 0 0"/>
    <axis xyz="0 0 -1"/>
    <limit effort="200.0" lower="-3.14" upper="1.57075" velocity="4"/>
    <parent link="link2_lr"/>
    <child link="link3_lr"/>
    <dynamics damping="10.0"/>
  </joint>
  <link name="link1_rr">
    <collision>
      <origin rpy="0 1.570797 0" xyz="0.044 0 0"/>
      <geometry>
        <cylinder length="0.088" radius="0.016"/>
      </geometry>
    </collision>
    <visual>
      <geometry>
        <cylinder length="0.088" radius="0.016"/>
      </geometry>
      <origin rpy="0 1.570797 0" xyz="0.044 0 0"/>
      <material name="blue"/>
    </visual>
    <inertial>
      <origin rpy="0 0 0" xyz="0.044 0 0"/>
      <mass value="0.9"/>
      <inertia ixx="0.0001152" ixy="0.0" ixz="0.0" iyy="0.0006384" iyz="0.0" izz="0.0006384"/>
    </inertial>
  </link>
  <gazebo reference="link1_rr">
    <kp>100000000.0</kp>
    <kd>10000000.0</kd>
    <mu1>1000000</mu1>
    <mu2>1000000</mu2>
    <material>Gazebo/Blue</material>
  </gazebo>
  <joint name="joint1_rr" type="revolute">
    <origin rpy="0 0 3.925" xyz="-0.15 -0.15 0"/>
    <axis xyz="0 0 -1"/>
    <limit effort="200.0" lower="-1.57075" upper="1.57075" velocity="4"/>
    <parent link="base_link"/>
    <child link="link1_rr"/>
    <dynamics damping="10.0"/>
  </joint>
  <link name="link2_rr">
    <collision>
      <geometry>
        <cylinder length="0.168" radius="0.016"/>
      </geometry>
      <origin rpy="0 -1.570797 0" xyz="0.084 0 0"/>
    </collision>
    <visual>
      <geometry>
        <cylinder length="0.168" radius="0.016"/>
      </geometry>
      <origin rpy="0 -1.570797 0" xyz="0.084 0 0"/>
      <material name="blue"/>
    </visual>
    <inertial>
      <origin rpy="0 0 0" xyz="0.084 0 0"/>
      <mass value="0.8"/>
      <inertia ixx="0.0001024" ixy="0.0" ixz="0.0" iyy="0.0019328" iyz="0.0" izz="0.0019328"/>
    </inertial>
  </link>
  <gazebo reference="link2_rr">
    <kp>100000000.0</kp>
    <kd>10000000.0</kd>
    <mu1>1000000</mu1>
    <mu2>1000000</mu2>
    <material>Gazebo/Blue</material>
  </gazebo>
  <joint name="joint2_rr" type="revolute">
    <origin rpy="1.570797 0 0" xyz="0.088 0 0"/>
    <axis xyz="0 0 -1"/>
    <limit effort="200.0" lower="-1.57075" upper="1.57075" velocity="4"/>
    <parent link="link1_rr"/>
    <child link="link2_rr"/>
    <dynamics damping="10.0"/>
  </joint>
  <link name="link3_rr">
    <collision>
      <geometry>
        <cylinder length="0.28" radius="0.016"/>
      </geometry>
      <origin rpy="0 -1.570797 0" xyz="0.14 0 0"/>
    </collision>
    <visual>
      <geometry>
        <cylinder length="0.28" radius="0.016"/>
      </geometry>
      <origin rpy="0 -1.570797 0" xyz="0.14 0 0"/>
      <material name="blue"/>
    </visual>
    <inertial>
      <origin rpy="0 0 0" xyz="0.14 0 0"/>
      <mass value="1.0"/>
      <inertia ixx="0.000128" ixy="0.0" ixz="0.0" iyy="0.00659733333333" iyz="0.0" izz="0.00659733333333"/>
    </inertial>
  </link>
  <gazebo reference="link3_rr">
    <kp>100000000.0</kp>
    <kd>10000000.0</kd>
    <mu1>1000000</mu1>
    <mu2>1000000</mu2>
    <material>Gazebo/Blue</material>
  </gazebo>
  <joint name="joint3_rr" type="revolute">
    <origin rpy="0 0 -1.570797" xyz="0.168 0 0"/>
    <axis xyz="0 0 -1"/>
    <limit effort="200.0" lower="-3.14" upper="1.57075" velocity="4"/>
    <parent link="link2_rr"/>
    <child link="link3_rr"/>
    <dynamics damping="10.0"/>
  </joint>
  <link name="link1_rf">
    <collision>
      <origin rpy="0 1.570797 0" xyz="0.044 0 0"/>
      <geometry>
        <cylinder length="0.088" radius="0.016"/>
      </geometry>
    </collision>
    <visual>
      <geometry>
        <cylinder length="0.088" radius="0.016"/>
      </geometry>
      <origin rpy="0 1.570797 0" xyz="0.044 0 0"/>
      <material name="blue"/>
    </visual>
    <inertial>
      <origin rpy="0 0 0" xyz="0.044 0 0"/>
      <mass value="0.9"/>
      <inertia ixx="0.0001152" ixy="0.0" ixz="0.0" iyy="0.0006384" iyz="0.0" izz="0.0006384"/>
    </inertial>
  </link>
  <gazebo reference="link1_rf">
    <kp>100000000.0</kp>
    <kd>10000000.0</kd>
    <mu1>1000000</mu1>
    <mu2>1000000</mu2>
    <material>Gazebo/Blue</material>
  </gazebo>
  <joint name="joint1_rf" type="revolute">
    <origin rpy="0 0 5.495" xyz="0.15 -0.15 0"/>
    <axis xyz="0 0 -1"/>
    <limit effort="200.0" lower="-1.57075" upper="1.57075" velocity="4"/>
    <parent link="base_link"/>
    <child link="link1_rf"/>
    <dynamics damping="10.0"/>
  </joint>
  <link name="link2_rf">
    <collision>
      <geometry>
        <cylinder length="0.168" radius="0.016"/>
      </geometry>
      <origin rpy="0 -1.570797 0" xyz="0.084 0 0"/>
    </collision>
    <visual>
      <geometry>
        <cylinder length="0.168" radius="0.016"/>
      </geometry>
      <origin rpy="0 -1.570797 0" xyz="0.084 0 0"/>
      <material name="blue"/>
    </visual>
    <inertial>
      <origin rpy="0 0 0" xyz="0.084 0 0"/>
      <mass value="0.8"/>
      <inertia ixx="0.0001024" ixy="0.0" ixz="0.0" iyy="0.0019328" iyz="0.0" izz="0.0019328"/>
    </inertial>
  </link>
  <gazebo reference="link2_rf">
    <kp>100000000.0</kp>
    <kd>10000000.0</kd>
    <mu1>1000000</mu1>
    <mu2>1000000</mu2>
    <material>Gazebo/Blue</material>
  </gazebo>
  <joint name="joint2_rf" type="revolute">
    <origin rpy="1.570797 0 0" xyz="0.088 0 0"/>
    <axis xyz="0 0 -1"/>
    <limit effort="200.0" lower="-1.57075" upper="1.57075" velocity="4"/>
    <parent link="link1_rf"/>
    <child link="link2_rf"/>
    <dynamics damping="10.0"/>
  </joint>
  <link name="link3_rf">
    <collision>
      <geometry>
        <cylinder length="0.28" radius="0.016"/>
      </geometry>
      <origin rpy="0 -1.570797 0" xyz="0.14 0 0"/>
    </collision>
    <visual>
      <geometry>
        <cylinder length="0.28" radius="0.016"/>
      </geometry>
      <origin rpy="0 -1.570797 0" xyz="0.14 0 0"/>
      <material name="blue"/>
    </visual>
    <inertial>
      <origin rpy="0 0 0" xyz="0.14 0 0"/>
      <mass value="1.0"/>
      <inertia ixx="0.000128" ixy="0.0" ixz="0.0" iyy="0.00659733333333" iyz="0.0" izz="0.00659733333333"/>
    </inertial>
  </link>
  <gazebo reference="link3_rf">
    <kp>100000000.0</kp>
    <kd>10000000.0</kd>
    <mu1>1000000</mu1>
    <mu2>1000000</mu2>
    <material>Gazebo/Blue</material>
  </gazebo>
  <joint name="joint3_rf" type="revolute">
    <origin rpy="0 0 -1.570797" xyz="0.168 0 0"/>
    <axis xyz="0 0 -1"/>
    <limit effort="200.0" lower="-3.14" upper="1.57075" velocity="4"/>
    <parent link="link2_rf"/>
    <child link="link3_rf"/>
    <dynamics damping="10.0"/>
  </joint>
  <transmission name="tran_joint1_lf">
    <type>transmission_interface/SimpleTransmission</type>
    <joint name="joint1_lf">
      <hardwareInterface>hardware_interface/PositionJointInterface</hardwareInterface>
    </joint>
    <actuator name="motor_joint1_lf">
      <hardwareInterface>hardware_interface/PositionJointInterface</hardwareInterface>
      <mechanicalReduction>1</mechanicalReduction>
    </actuator>
  </transmission>
  <transmission name="tran_joint1_lr">
    <type>transmission_interface/SimpleTransmission</type>
    <joint name="joint1_lr">
      <hardwareInterface>hardware_interface/PositionJointInterface</hardwareInterface>
    </joint>
    <actuator name="motor_joint1_lr">
      <hardwareInterface>hardware_interface/PositionJointInterface</hardwareInterface>
      <mechanicalReduction>1</mechanicalReduction>
    </actuator>
  </transmission>
  <transmission name="tran_joint1_rr">
    <type>transmission_interface/SimpleTransmission</type>
    <joint name="joint1_rr">
      <hardwareInterface>hardware_interface/PositionJointInterface</hardwareInterface>
    </joint>
    <actuator name="motor_joint1_rr">
      <hardwareInterface>hardware_interface/PositionJointInterface</hardwareInterface>
      <mechanicalReduction>1</mechanicalReduction>
    </actuator>
  </transmission>
  <transmission name="tran_joint1_rf">
    <type>transmission_interface/SimpleTransmission</type>
    <joint name="joint1_rf">
      <hardwareInterface>hardware_interface/PositionJointInterface</hardwareInterface>
    </joint>
    <actuator name="motor_joint1_rf">
      <hardwareInterface>hardware_interface/PositionJointInterface</hardwareInterface>
      <mechanicalReduction>1</mechanicalReduction>
    </actuator>
  </transmission>
  <transmission name="tran_joint2_lf">
    <type>transmission_interface/SimpleTransmission</type>
    <joint name="joint2_lf">
      <hardwareInterface>hardware_interface/PositionJointInterface</hardwareInterface>
    </joint>
    <actuator name="motor_joint2_lf">
      <hardwareInterface>hardware_interface/PositionJointInterface</hardwareInterface>
      <mechanicalReduction>1</mechanicalReduction>
    </actuator>
  </transmission>
  <transmission name="tran_joint2_lr">
    <type>transmission_interface/SimpleTransmission</type>
    <joint name="joint2_lr">
      <hardwareInterface>hardware_interface/PositionJointInterface</hardwareInterface>
    </joint>
    <actuator name="motor_joint2_lr">
      <hardwareInterface>hardware_interface/PositionJointInterface</hardwareInterface>
      <mechanicalReduction>1</mechanicalReduction>
    </actuator>
  </transmission>
  <transmission name="tran_joint2_rr">
    <type>transmission_interface/SimpleTransmission</type>
    <joint name="joint2_rr">
      <hardwareInterface>hardware_interface/PositionJointInterface</hardwareInterface>
    </joint>
    <actuator name="motor_joint2_rr">
      <hardwareInterface>hardware_interface/PositionJointInterface</hardwareInterface>
      <mechanicalReduction>1</mechanicalReduction>
    </actuator>
  </transmission>
  <transmission name="tran_joint2_rf">
    <type>transmission_interface/SimpleTransmission</type>
    <joint name="joint2_rf">
      <hardwareInterface>hardware_interface/PositionJointInterface</hardwareInterface>
    </joint>
    <actuator name="motor_joint2_rf">
      <hardwareInterface>hardware_interface/PositionJointInterface</hardwareInterface>
      <mechanicalReduction>1</mechanicalReduction>
    </actuator>
  </transmission>
  <transmission name="tran_joint3_lf">
    <type>transmission_interface/SimpleTransmission</type>
    <joint name="joint3_lf">
      <hardwareInterface>hardware_interface/PositionJointInterface</hardwareInterface>
    </joint>
    <actuator name="motor_joint3_lf">
      <hardwareInterface>hardware_interface/PositionJointInterface</hardwareInterface>
      <mechanicalReduction>1</mechanicalReduction>
    </actuator>
  </transmission>
  <transmission name="tran_joint3_lr">
    <type>transmission_interface/SimpleTransmission</type>
    <joint name="joint3_lr">
      <hardwareInterface>hardware_interface/PositionJointInterface</hardwareInterface>
    </joint>
    <actuator name="motor_joint3_lr">
      <hardwareInterface>hardware_interface/PositionJointInterface</hardwareInterface>
      <mechanicalReduction>1</mechanicalReduction>
    </actuator>
  </transmission>
  <transmission name="tran_joint3_rr">
    <type>transmission_interface/SimpleTransmission</type>
    <joint name="joint3_rr">
      <hardwareInterface>hardware_interface/PositionJointInterface</hardwareInterface>
    </joint>
    <actuator name="motor_joint3_rr">
      <hardwareInterface>hardware_interface/PositionJointInterface</hardwareInterface>
      <mechanicalReduction>1</mechanicalReduction>
    </actuator>
  </transmission>
  <transmission name="tran_joint3_rf">
    <type>transmission_interface/SimpleTransmission</type>
    <joint name="joint3_rf">
      <hardwareInterface>hardware_interface/PositionJointInterface</hardwareInterface>
    </joint>
    <actuator name="motor_joint3_rf">
      <hardwareInterface>hardware_interface/PositionJointInterface</hardwareInterface>
      <mechanicalReduction>1</mechanicalReduction>
    </actuator>
  </transmission>
  <!--ROS Control plugin is required for ros to communicate to Gazebo for
    controlling the robot-->
  <gazebo>
    <plugin filename="libgazebo_ros_control.so" name="gazebo_ros_control">
      <legacyModeNS>true</legacyModeNS>
      <!--To avoid the legacyMode Warning-->
      <!--https://answers.ros.org/question/292444/gazebo_ros_control-plugin-gazeboroscontrolplugin-missing-legacymodens-defaultrobothwsim/-->
    </plugin>
  </gazebo>
</robot>
